[07/09/2025 19:31:27,87] Launch run_retention_cli.py
[retention] {'soft_deleted': 0, 'purged': 0}
[07/09/2025 19:31:29,31] Exit code 0
[07/09/2025 19:31:47,57] Launch run_retention_cli.py
[retention] {'soft_deleted': 0, 'purged': 0}
[07/09/2025 19:31:48,80] Exit code 0
[08/09/2025  3:00:01,73] Launch run_retention_cli.py
Traceback (most recent call last):
  File "C:\Users\henry\Desktop\freshkeeper-backend-phase3\.venv\Lib\site-packages\sqlalchemy\engine\base.py", line 143, in __init__
    self._dbapi_connection = engine.raw_connection()
                             ^^^^^^^^^^^^^^^^^^^^^^^
  File "C:\Users\henry\Desktop\freshkeeper-backend-phase3\.venv\Lib\site-packages\sqlalchemy\engine\base.py", line 3301, in raw_connection
    return self.pool.connect()
           ^^^^^^^^^^^^^^^^^^^
  File "C:\Users\henry\Desktop\freshkeeper-backend-phase3\.venv\Lib\site-packages\sqlalchemy\pool\base.py", line 447, in connect
    return _ConnectionFairy._checkout(self)
           ^^^^^^^^^^^^^^^^^^^^^^^^^^^^^^^^
  File "C:\Users\henry\Desktop\freshkeeper-backend-phase3\.venv\Lib\site-packages\sqlalchemy\pool\base.py", line 1264, in _checkout
    fairy = _ConnectionRecord.checkout(pool)
            ^^^^^^^^^^^^^^^^^^^^^^^^^^^^^^^^
  File "C:\Users\henry\Desktop\freshkeeper-backend-phase3\.venv\Lib\site-packages\sqlalchemy\pool\base.py", line 711, in checkout
    rec = pool._do_get()
          ^^^^^^^^^^^^^^
  File "C:\Users\henry\Desktop\freshkeeper-backend-phase3\.venv\Lib\site-packages\sqlalchemy\pool\impl.py", line 177, in _do_get
    with util.safe_reraise():
         ^^^^^^^^^^^^^^^^^^^
  File "C:\Users\henry\Desktop\freshkeeper-backend-phase3\.venv\Lib\site-packages\sqlalchemy\util\langhelpers.py", line 224, in __exit__
    raise exc_value.with_traceback(exc_tb)
  File "C:\Users\henry\Desktop\freshkeeper-backend-phase3\.venv\Lib\site-packages\sqlalchemy\pool\impl.py", line 175, in _do_get
    return self._create_connection()
           ^^^^^^^^^^^^^^^^^^^^^^^^^
  File "C:\Users\henry\Desktop\freshkeeper-backend-phase3\.venv\Lib\site-packages\sqlalchemy\pool\base.py", line 388, in _create_connection
    return _ConnectionRecord(self)
           ^^^^^^^^^^^^^^^^^^^^^^^
  File "C:\Users\henry\Desktop\freshkeeper-backend-phase3\.venv\Lib\site-packages\sqlalchemy\pool\base.py", line 673, in __init__
    self.__connect()
  File "C:\Users\henry\Desktop\freshkeeper-backend-phase3\.venv\Lib\site-packages\sqlalchemy\pool\base.py", line 899, in __connect
    with util.safe_reraise():
         ^^^^^^^^^^^^^^^^^^^
  File "C:\Users\henry\Desktop\freshkeeper-backend-phase3\.venv\Lib\site-packages\sqlalchemy\util\langhelpers.py", line 224, in __exit__
    raise exc_value.with_traceback(exc_tb)
  File "C:\Users\henry\Desktop\freshkeeper-backend-phase3\.venv\Lib\site-packages\sqlalchemy\pool\base.py", line 895, in __connect
    self.dbapi_connection = connection = pool._invoke_creator(self)
                                         ^^^^^^^^^^^^^^^^^^^^^^^^^^
  File "C:\Users\henry\Desktop\freshkeeper-backend-phase3\.venv\Lib\site-packages\sqlalchemy\engine\create.py", line 661, in connect
    return dialect.connect(*cargs, **cparams)
           ^^^^^^^^^^^^^^^^^^^^^^^^^^^^^^^^^^
  File "C:\Users\henry\Desktop\freshkeeper-backend-phase3\.venv\Lib\site-packages\sqlalchemy\engine\default.py", line 629, in connect
    return self.loaded_dbapi.connect(*cargs, **cparams)  # type: ignore[no-any-return]  # NOQA: E501
           ^^^^^^^^^^^^^^^^^^^^^^^^^^^^^^^^^^^^^^^^^^^^
  File "C:\Users\henry\Desktop\freshkeeper-backend-phase3\.venv\Lib\site-packages\psycopg\connection.py", line 118, in connect
    raise last_ex.with_traceback(None)
psycopg.OperationalError: connection failed: connection to server at "127.0.0.1", port 5432 failed: FATAL:  authentification par mot de passe �chou�e pour l'utilisateur  � frigo_user �

The above exception was the direct cause of the following exception:

Traceback (most recent call last):
  File "C:\Users\henry\Desktop\freshkeeper-backend-phase3\scripts\run_retention_cli.py", line 32, in <module>
    main()
  File "C:\Users\henry\Desktop\freshkeeper-backend-phase3\scripts\run_retention_cli.py", line 26, in main
    out = run_retention(db, retention_days=None)  # None => valeur par défaut dans le service
          ^^^^^^^^^^^^^^^^^^^^^^^^^^^^^^^^^^^^^^
  File "C:\Users\henry\Desktop\freshkeeper-backend-phase3\freshkeeper\services\alert_maintenance.py", line 71, in run_retention
    soft = soft_delete_old_alerts(db, retention_days=retention_days)
           ^^^^^^^^^^^^^^^^^^^^^^^^^^^^^^^^^^^^^^^^^^^^^^^^^^^^^^^^^
  File "C:\Users\henry\Desktop\freshkeeper-backend-phase3\freshkeeper\services\alert_maintenance.py", line 51, in soft_delete_old_alerts
    res = db.execute(sql, {"now": now, "cutoff": cutoff})
          ^^^^^^^^^^^^^^^^^^^^^^^^^^^^^^^^^^^^^^^^^^^^^^^
  File "C:\Users\henry\Desktop\freshkeeper-backend-phase3\.venv\Lib\site-packages\sqlalchemy\orm\session.py", line 2365, in execute
    return self._execute_internal(
           ^^^^^^^^^^^^^^^^^^^^^^^
  File "C:\Users\henry\Desktop\freshkeeper-backend-phase3\.venv\Lib\site-packages\sqlalchemy\orm\session.py", line 2241, in _execute_internal
    conn = self._connection_for_bind(bind)
           ^^^^^^^^^^^^^^^^^^^^^^^^^^^^^^^
  File "C:\Users\henry\Desktop\freshkeeper-backend-phase3\.venv\Lib\site-packages\sqlalchemy\orm\session.py", line 2110, in _connection_for_bind
    return trans._connection_for_bind(engine, execution_options)
           ^^^^^^^^^^^^^^^^^^^^^^^^^^^^^^^^^^^^^^^^^^^^^^^^^^^^^
  File "<string>", line 2, in _connection_for_bind
  File "C:\Users\henry\Desktop\freshkeeper-backend-phase3\.venv\Lib\site-packages\sqlalchemy\orm\state_changes.py", line 137, in _go
    ret_value = fn(self, *arg, **kw)
                ^^^^^^^^^^^^^^^^^^^^
  File "C:\Users\henry\Desktop\freshkeeper-backend-phase3\.venv\Lib\site-packages\sqlalchemy\orm\session.py", line 1189, in _connection_for_bind
    conn = bind.connect()
           ^^^^^^^^^^^^^^
  File "C:\Users\henry\Desktop\freshkeeper-backend-phase3\.venv\Lib\site-packages\sqlalchemy\engine\base.py", line 3277, in connect
    return self._connection_cls(self)
           ^^^^^^^^^^^^^^^^^^^^^^^^^^
  File "C:\Users\henry\Desktop\freshkeeper-backend-phase3\.venv\Lib\site-packages\sqlalchemy\engine\base.py", line 145, in __init__
    Connection._handle_dbapi_exception_noconnection(
  File "C:\Users\henry\Desktop\freshkeeper-backend-phase3\.venv\Lib\site-packages\sqlalchemy\engine\base.py", line 2440, in _handle_dbapi_exception_noconnection
    raise sqlalchemy_exception.with_traceback(exc_info[2]) from e
  File "C:\Users\henry\Desktop\freshkeeper-backend-phase3\.venv\Lib\site-packages\sqlalchemy\engine\base.py", line 143, in __init__
    self._dbapi_connection = engine.raw_connection()
                             ^^^^^^^^^^^^^^^^^^^^^^^
  File "C:\Users\henry\Desktop\freshkeeper-backend-phase3\.venv\Lib\site-packages\sqlalchemy\engine\base.py", line 3301, in raw_connection
    return self.pool.connect()
           ^^^^^^^^^^^^^^^^^^^
  File "C:\Users\henry\Desktop\freshkeeper-backend-phase3\.venv\Lib\site-packages\sqlalchemy\pool\base.py", line 447, in connect
    return _ConnectionFairy._checkout(self)
           ^^^^^^^^^^^^^^^^^^^^^^^^^^^^^^^^
  File "C:\Users\henry\Desktop\freshkeeper-backend-phase3\.venv\Lib\site-packages\sqlalchemy\pool\base.py", line 1264, in _checkout
    fairy = _ConnectionRecord.checkout(pool)
            ^^^^^^^^^^^^^^^^^^^^^^^^^^^^^^^^
  File "C:\Users\henry\Desktop\freshkeeper-backend-phase3\.venv\Lib\site-packages\sqlalchemy\pool\base.py", line 711, in checkout
    rec = pool._do_get()
          ^^^^^^^^^^^^^^
  File "C:\Users\henry\Desktop\freshkeeper-backend-phase3\.venv\Lib\site-packages\sqlalchemy\pool\impl.py", line 177, in _do_get
    with util.safe_reraise():
         ^^^^^^^^^^^^^^^^^^^
  File "C:\Users\henry\Desktop\freshkeeper-backend-phase3\.venv\Lib\site-packages\sqlalchemy\util\langhelpers.py", line 224, in __exit__
    raise exc_value.with_traceback(exc_tb)
  File "C:\Users\henry\Desktop\freshkeeper-backend-phase3\.venv\Lib\site-packages\sqlalchemy\pool\impl.py", line 175, in _do_get
    return self._create_connection()
           ^^^^^^^^^^^^^^^^^^^^^^^^^
  File "C:\Users\henry\Desktop\freshkeeper-backend-phase3\.venv\Lib\site-packages\sqlalchemy\pool\base.py", line 388, in _create_connection
    return _ConnectionRecord(self)
           ^^^^^^^^^^^^^^^^^^^^^^^
  File "C:\Users\henry\Desktop\freshkeeper-backend-phase3\.venv\Lib\site-packages\sqlalchemy\pool\base.py", line 673, in __init__
    self.__connect()
  File "C:\Users\henry\Desktop\freshkeeper-backend-phase3\.venv\Lib\site-packages\sqlalchemy\pool\base.py", line 899, in __connect
    with util.safe_reraise():
         ^^^^^^^^^^^^^^^^^^^
  File "C:\Users\henry\Desktop\freshkeeper-backend-phase3\.venv\Lib\site-packages\sqlalchemy\util\langhelpers.py", line 224, in __exit__
    raise exc_value.with_traceback(exc_tb)
  File "C:\Users\henry\Desktop\freshkeeper-backend-phase3\.venv\Lib\site-packages\sqlalchemy\pool\base.py", line 895, in __connect
    self.dbapi_connection = connection = pool._invoke_creator(self)
                                         ^^^^^^^^^^^^^^^^^^^^^^^^^^
  File "C:\Users\henry\Desktop\freshkeeper-backend-phase3\.venv\Lib\site-packages\sqlalchemy\engine\create.py", line 661, in connect
    return dialect.connect(*cargs, **cparams)
           ^^^^^^^^^^^^^^^^^^^^^^^^^^^^^^^^^^
  File "C:\Users\henry\Desktop\freshkeeper-backend-phase3\.venv\Lib\site-packages\sqlalchemy\engine\default.py", line 629, in connect
    return self.loaded_dbapi.connect(*cargs, **cparams)  # type: ignore[no-any-return]  # NOQA: E501
           ^^^^^^^^^^^^^^^^^^^^^^^^^^^^^^^^^^^^^^^^^^^^
  File "C:\Users\henry\Desktop\freshkeeper-backend-phase3\.venv\Lib\site-packages\psycopg\connection.py", line 118, in connect
    raise last_ex.with_traceback(None)
sqlalchemy.exc.OperationalError: (psycopg.OperationalError) connection failed: connection to server at "127.0.0.1", port 5432 failed: FATAL:  authentification par mot de passe �chou�e pour l'utilisateur  � frigo_user �
(Background on this error at: https://sqlalche.me/e/20/e3q8)
[08/09/2025  3:00:03,56] Exit code 1
[09/09/2025  3:00:01,70] Launch run_retention_cli.py
[retention] {'soft_deleted': 0, 'purged': 0}
